<mujoco model="left_hand">
  <geom type="mesh" rgba="0.7 0.7 0.7 1" mesh="left_base_link" contype="0" conaffinity="0" quat="0 0 0.707 0.707"/>
  <geom type="mesh" rgba="0.7 0.7 0.7 1" mesh="meta2_1" contype="1" conaffinity="1"/>
  <geom type="mesh" rgba="0.7 0.7 0.7 1" mesh="meta1_1" contype="1" conaffinity="1"/>
  <geom type="mesh" rgba="0.7 0.7 0.7 1" mesh="meta3_1" contype="1" conaffinity="1"/>
  <geom type="mesh" rgba="0.7 0.7 0.7 1" mesh="meta4_1" contype="1" conaffinity="1"/>
  
  <body name="left_palm" pos="0 0 0">
      <!-- <inertial<inertial pos="0.00012921570168839317 0.017296271435922838 0.004513375763540404" mass="0.038866249408726565" diaginertia="1.6e-05 2.3e-05 2.4e-05"/>/> -->
      <body name="left_mcp2_1" pos="-0.029022 0.100047 -0.013279">
          <!-- <inertial<inertial pos="-0.00085722 0.00842528 0.00865166" quat="0.707107 0.707107 0 0" mass="0.0150899" diaginertia="2e-06 2e-06 1e-06" />/> -->
          <joint name="left_aa2" pos="0 0 0" axis="0 -0.173648 0.984808" limited="true" range="-3.14 3.14" class="ksy_joint"/>
          <geom pos="0.029022 -0.100047 0.013279" type="mesh" rgba="0.7 0.7 0.7 1" mesh="mcp2_1" contype="2" conaffinity="2"/>
          <body name="left_pp2_1" pos="-0.008953 0.01468 0.010509">
              <!-- <inertial<inertial pos="0.00558963 0.0222004 0.00172825" quat="0.707107 0.707107 0 0" mass="0.0125687" diaginertia="3e-06 3e-06 2e-06" />/> -->
              <joint name="left_mcp2" pos="0 0 0" axis="-0.996195 -0.085832 -0.015134" limited="true" range="-3.14 3.14" class="ksy_joint" />
              <geom pos="0.037975 -0.114727 0.00277" type="mesh" rgba="0.7 0.7 0.7 1" mesh="pp2_1"/>
              <body name="left_mp2_1" pos="-0.003931 0.039809 -3.3e-05">
                  <!-- <inertial<inertial pos="0.00676453 0.0144678 0.00126187" quat="0.707107 0.707107 0 0" mass="0.0129842" diaginertia="2e-06 2e-06 1e-06" />/> -->
                  <joint name="left_pip2" pos="0 0 0" axis="-0.996195 -0.085832 -0.015134"  limited="true" range="-3.14 3.14" class="ksy_joint"/>
                  <geom pos="0.041906 -0.154536 0.002803" type="mesh" rgba="0.7 0.7 0.7 1" mesh="mp2_1" />
                  <body name="left_dp2_1" pos="8.7e-05 0.028112 1.9e-05">
                      <!-- <inertial<inertial pos="0.00429285 0.0142959 -0.000246767" mass="0.0151738" diaginertia="1e-06 1e-06 1e-06" />/> -->
                      <joint name="left_dip2" pos="0 0 0" axis="-0.996195 -0.085832 -0.015134" limited="true" range="-3.14 3.14" class="ksy_joint"/>
                      <geom pos="0.041819 -0.182648 0.002784" type="mesh" rgba="0.7 0.7 0.7 1" mesh="dp2_1" />
                  </body>
              </body>
          </body>
          <body name="left_act2_1" pos="0.001613 0.018389 0.02081">
              <!-- <inertial<inertial pos="-0.00292034 -0.00937475 0.0141296" quat="0.707107 0.707107 0 0" mass="0.050027" diaginertia="1e-05 8e-06 6e-06" />/> -->
              <joint name="left_act2" pos="0 0 0" axis="-0.996195 -0.085832 -0.015134" limited="true" range="-3.14 3.14" class="ksy_joint" />
              <geom pos="0.027409 -0.118436 -0.007531" type="mesh" rgba="0.7 0.7 0.7 1" mesh="act2_1" contype="4" conaffinity="4" />
          </body>
      </body>
      <body name="left_mcp1_1" pos="-0.029913 0.05726 -0.033338">
          <!-- <inertial<inertial pos="-0.0118924 -0.00197871 0.00110107" quat="0.5 0.5 0.5 0.5" mass="0.0150899" diaginertia="2e-06 2e-06 1e-06" />/> -->
          <joint name="left_aa1" pos="0 0 0" axis="-0.42367 -0.700574 -0.574195" limited="true" range="-3.14 3.14" class="ksy_joint"/> <!--z 값 음수-->
          <geom pos="0.029913 -0.05726 0.033338" type="mesh" rgba="0.7 0.7 0.7 1" mesh="mcp1_1" contype="2" conaffinity="2"/>
          <body name="left_pp1_1" pos="-0.018968 0.004511 0.005092">
              <!-- <inertial<inertial pos="-0.0183518 0.00316656 -0.0134266" quat="0.5 0.5 0.5 0.5" mass="0.0125687" diaginertia="3e-06 3e-06 2e-06" />/> -->
              <joint name="left_mcp1" pos="0 0 0" axis="0.037066 -0.646775 0.76178" limited="true" range="-3.14 3.14" class="ksy_joint"/><!-- z 값 양수-->
              <geom pos="0.048881 -0.061771 0.028246" type="mesh" rgba="0.7 0.7 0.7 1" mesh="pp1_1"/>
              <body name="left_mp1_1" pos="-0.032135 0.006716 -0.027613">
                  <!-- <inertial<inertial pos="-0.012269 0.0102303 0.00121932" quat="0.5 0.5 0.5 0.5" mass="0.0129842" diaginertia="2e-06 2e-06 1e-06" />/> -->
                  <joint name="left_pip1" pos="0 0 0" axis="0.037066 -0.646775 0.76178" limited="true" range="-3.14 3.14" class="ksy_joint"/>  <!-- z 값 양수-->
                  <geom pos="0.081016 -0.068487 0.055859" type="mesh" rgba="0.7 0.7 0.7 1" mesh="mp1_1" />
                  <body name="left_dp1_1" pos="-0.023397 0.020451 -0.00078">
                      <!-- <inertial<inertial pos="-0.0109583 0.00245434 -0.00983685" mass="0.0151738" diaginertia="1e-06 1e-06 1e-06" />/> -->
                      <joint name="left_dip1" pos="0 0 0" axis="0.037066 -0.646775 -0.76178" limited="true" range="-3.14 3.14" class="ksy_joint"/>
                      <geom pos="0.104413 -0.088938 0.056639" type="mesh" rgba="0.7 0.7 0.7 1" mesh="dp1_1" />
                  </body>
              </body>
          </body>
          <body name="left_act1_1" pos="-0.026658 -0.007903 0.000818">
              <!-- <inertial<inertial pos="-0.000833478 -0.010584 0.0135401" quat="0.433758 0.539223 -0.0208348 0.721567" mass="0.050027" diaginertia="1.05688e-05 7.63555e-06 4.7956e-06" />/> -->
              <joint name="left_act1" pos="0 0 0" axis="0.037066 -0.646775 -0.76178" limited="true" range="-3.14 3.14" class="ksy_joint" />
              <geom pos="0.056571 -0.049357 0.03252" type="mesh" rgba="0.7 0.7 0.7 1" mesh="act1_1" contype="4" conaffinity="4" />
          </body>
      </body>
      <body name="left_mcp3_1" pos="0.00045 0.101099 -0.013093">
          <!-- <inertial<inertial pos="3.79376e-07 0.00846239 0.0086577" quat="0.707107 0.707107 0 0" mass="0.0150899" diaginertia="2e-06 2e-06 1e-06" />/> -->
          <joint name="left_aa3" pos="0 0 0" axis="0 -0.173648 0.984808" limited="true" range="-3.14 3.14" class="ksy_joint"/>
          <geom pos="-0.00045 -0.101099 0.013093" type="mesh" rgba="0.7 0.7 0.7 1" mesh="mcp3_1" contype="2" conaffinity="2" />
          <body name="left_pp3_1" pos="0.0075 0.015388 0.010633">
              <!-- <inertial<inertial pos="-0.00749962 0.0216372 0.00162929" quat="0.707107 0.707107 0 0" mass="0.0125687" diaginertia="3e-06 3e-06 2e-06" />/> -->
              <joint name="left_mcp3" pos="0 0 0" axis="-1 0 0" limited="true" range="-3.14 3.14" class="ksy_joint"/>
              <geom pos="-0.00795 -0.116487 0.00246" type="mesh" rgba="0.7 0.7 0.7 1" mesh="pp3_1"/>
              <body name="left_mp3_1" pos="-0.0155 0.04 0">
                  <!-- <inertial<inertial pos="0.00800038 0.0138322 0.00115081" quat="0.707107 0.707107 0 0" mass="0.0129842" diaginertia="2e-06 2e-06 1e-06" />/> -->
                  <joint name="left_pip3" pos="0 0 0" axis="-1 0 0" limited="true" range="-3.14 3.14" class="ksy_joint"/>
                  <geom pos="0.00755 -0.156487 0.00246" type="mesh" rgba="0.7 0.7 0.7 1" mesh="mp3_1" />
                  <body name="left_dp3_1" pos="0.0135 0.028 0">
                      <!-- <inertial<inertial pos="-0.00549962 0.0138749 -0.000320751" mass="0.0151738" diaginertia="1e-06 1e-06 1e-06" />/> -->
                      <joint name="left_dip3" pos="0 0 0" axis="-1 0 0" limited="true" range="-3.14 3.14" class="ksy_joint"/>
                      <geom pos="-0.00595 -0.184487 0.00246" type="mesh" rgba="0.7 0.7 0.7 1" mesh="dp3_1" />
                  </body>
              </body>
          </body>
          <body name="left_act3_1" pos="0.0035 0.01817 0.020771">
              <!-- <inertial<inertial pos="-0.00349962 -0.00909928 0.0141781" quat="0.707107 0.707107 0 0" mass="0.050027" diaginertia="1e-05 8e-06 6e-06" />/> -->
              <joint name="left_act3" pos="0 0 0" axis="-1 0 0" limited="true" range="-3.14 3.14" class="ksy_joint" />
              <geom pos="-0.00395 -0.119269 -0.007678" type="mesh" rgba="0.7 0.7 0.7 1" mesh="act3_1" contype="4" conaffinity="4" />
          </body>
      </body>
      <body name="left_mcp4_1" pos="0.029803 0.092965 -0.014527">
          <!-- <inertial<inertial pos="0.000857375 0.00842528 0.00865091" quat="0.707107 0.707107 0 0" mass="0.0150899" diaginertia="2e-06 2e-06 1e-06" />/> -->
          <joint name="left_aa4" pos="0 0 0" axis="0 -0.173648 0.984808" limited="true" range="-3.14 3.14" class="ksy_joint"/>
          <geom pos="-0.029803 -0.092965 0.014527" type="mesh" rgba="0.7 0.7 0.7 1" mesh="mcp4_1" contype="2" conaffinity="2"/>
          <body name="left_pp4_1" pos="0.008953 0.01468 0.010508">
              <!-- <inertial<inertial pos="-0.00558948 0.0222003 0.00172851" quat="0.707107 0.707107 0 0" mass="0.0125687" diaginertia="3e-06 3e-06 2e-06" />/> -->
              <joint name="left_mcp4" pos="0 0 0" axis="-0.996195 0.085832 0.015134" limited="true" range="-3.14 3.14" class="ksy_joint"/>
              <geom pos="-0.038756 -0.107645 0.004019" type="mesh" rgba="0.7 0.7 0.7 1" mesh="pp4_1" />
              <body name="left_mp4_1" pos="-0.012008 0.041183 0.000209">
                  <!-- <inertial<inertial pos="0.00917463 0.0130938 0.00102012" quat="0.707107 0.707107 0 0" mass="0.0129842" diaginertia="2e-06 2e-06 1e-06" />/> -->
                  <joint name="left_pip4" pos="0 0 0" axis="-1 0 0" limited="true" range="-3.14 3.14" class="ksy_joint"/>
                  <geom pos="-0.026748 -0.148828 0.00381" type="mesh" rgba="0.7 0.7 0.7 1" mesh="mp4_1" />
                  <body name="left_dp4_1" pos="0.015852 0.026738 -0.000223">
                      <!-- <inertial<inertial pos="-0.00429269 0.0142959 -0.000246515" mass="0.0151738" diaginertia="1e-06 1e-06 1e-06" />/> -->
                      <joint name="left_dip4" pos="0 0 0" axis="-0.996195 0.085832 0.015134" limited="true" range="-3.14 3.14" class="ksy_joint"/>
                      <geom pos="-0.0426 -0.175566 0.004033" type="mesh" rgba="0.7 0.7 0.7 1" mesh="dp4_1" />
                  </body>
              </body>
          </body>
          <body name="left_act4_1" pos="0.005361 0.017788 0.020703">
              <!-- <inertial<inertial pos="-0.00405351 -0.00877375 0.0142359" quat="0.707107 0.707107 0 0" mass="0.050027" diaginertia="1e-05 8e-06 6e-06" />/> -->
              <joint name="left_act4" pos="0 0 0" axis="-0.996195 0.085832 0.015134" limited="true" range="-3.14 3.14" class="ksy_joint" />
              <geom pos="-0.035164 -0.110753 -0.006176" type="mesh" rgba="0.7 0.7 0.7 1" mesh="act4_1" contype="4" conaffinity="4" />
          </body>
      </body>
  </body>

  <actuator>
    <include file="sh_hand_left_actuator.xml"/>
  </actuator>
</mujoco>
